<?xml version='1.0'?>
<sdf version='1.4'>
  <model name="my_robot">
    <link name='chassis'>
      <pose>0 0 .1 0 0 0</pose>
      <collision name='collision'>
        <geometry>
          <box>
            <size>0.9 0.7 .3</size>
          </box>
        </geometry>
      </collision>
      <visual name='visual'>
        <geometry>
          <box>
            <size>0.9 0.7 .3</size>
          </box>
        </geometry>
      </visual>

      <collision name='caster_collision'>
        <pose>-0.25 0 -0.1 0 0 0</pose>
        <geometry>
          <sphere>
            <radius>.1</radius>
          </sphere>
        </geometry>

        <surface>
          <friction>
            <ode>
              <mu>0</mu>
              <mu2>0</mu2>
              <slip1>1.0</slip1>
              <slip2>1.0</slip2>
            </ode>
          </friction>
        </surface>
      </collision>

      <visual name='caster_visual'>
        <pose>-0.25 0 -0.1 0 0 0</pose>
        <geometry>
          <sphere>
            <radius>.1</radius>
          </sphere>
        </geometry>
      </visual>
    </link>

    <link name="left_wheel">
      <pose>0.15 0.40 0.1 0 1.5707 1.5707</pose>
      <collision name="collision">
        <geometry>
          <cylinder>
            <radius>.2</radius>
            <length>.1</length>
          </cylinder>
        </geometry>
      </collision>
      <visual name="visual">
        <geometry>
          <cylinder>
            <radius>.2</radius>
            <length>.15</length>
          </cylinder>
        </geometry>
      </visual>
    </link>

    <link name="right_wheel">
      <pose>0.15 -0.40 0.1 0 1.5707 1.5707</pose>
      <collision name="collision">
        <geometry>
          <cylinder>
            <radius>.2</radius>
            <length>.1</length>
          </cylinder>
        </geometry>
      </collision>
      <visual name="visual">
        <geometry>
          <cylinder>
            <radius>.2</radius>
            <length>.15</length>
          </cylinder>
        </geometry>
      </visual>
    </link>

    <joint type="revolute" name="left_wheel_hinge">
      <pose>0 0 -0.03 0 0 0</pose>
      <child>left_wheel</child>
      <parent>chassis</parent>
      <axis>
        <xyz>0 1 0</xyz>
      </axis>
    </joint>

    <joint type="revolute" name="right_wheel_hinge">
      <pose>0 0 0.03 0 0 0</pose>
      <child>right_wheel</child>
      <parent>chassis</parent>
      <axis>
        <xyz>0 1 0</xyz>
      </axis>
    </joint>

    <link name="Lidar">
      <pose> 0.2 0 0.28 0 -0 0 </pose>
        <visual name="visual">
          <geometry>
            <mesh>
              <uri>model://hokuyo/meshes/hokuyo.dae</uri>
            </mesh>
          </geometry>
        </visual>
    </link>
    <joint type="fixed" name="Lidar_hinge">
      <pose>0 0 0.03 0 0 0</pose>
      <child>Lidar</child>
      <parent>chassis</parent>
      <axis>
        <xyz>0 0 1</xyz>
      </axis>
    </joint>
  </model>
 </sdf>

